Workbook

Sheet Sheet1
A1: Table Name | B1: Table With Data | C1: Script Type
A2: OTPRequests | B2: NO
A3: RegisteredDevices | B3: NO
A4: tblAccountType | B4: YES | C4: Use Exists
A5: tblAppConfig | B5: YES | C5: Use Exists
A6: tblAppPasswordSettings | B6: YES | C6: Use Exists
A7: tblBeatSalesmanMapping | B7: NO
A8: tblCollPMDetails | B8: NO
A9: tblColorSettings | B9: YES | C9: Use Exists
A10: tblCompanyRegistration | B10: NO
A11: tblContraMode | B11: YES | C11: Use Exists
A12: tblContraType | B12: YES | C12: Use Exists
A13: tblDocumentSeries | B13: YES
A14: tblFAAccount | B14: YES | C14: Use Exists
A15: tblFAGroup | B15: YES | C15: Use Exists
A16: tblFAJournal | B16: NO
A17: tblFAJournelCancel | B17: NO
A18: tblFAType | B18: YES | C18: Use Exists
A19: tblFilterDates | B19: YES | C19: Use Exists
A20: tblGSTStateNameandCode | B20: YES | C20: Use Exists
A21: tblInventoryDetail | B21: NO
A22: tblInventoryHeader | B22: NO
A23: tblMasterBank | B23: YES | C23: Use Exists
A24: tblMasterBankAccount | B24: NO
A25: tblMasterBeat | B25: NO
A26: tblMasterBranchOffice | B26: NO
A27: tblMasterBrand | B27: NO
A28: tblMasterCategory | B28: NO
A29: tblMasterChequeBook | B29: NO
A30: tblMasterChequeBookDetail | B30: NO
A31: tblMasterCreditTerm | B31: NO
A32: tblMasterCustomer | B32: NO
A33: tblMasterCustomerRemarks | B33: NO
A34: tblMasterCustomerType | B34: NO
A35: tblMasterCustomerVendorHistory | B35: NO
... A46: tblMasterReturnType | B46: NO
A47: tblMasterRole | B47: YES | C47: Use Exists
A48: tblMasterSalesman | B48: NO
A49: tblMasterSalesmanGroup | B49: NO
A50: tblMasterService | B50: NO
...

Sheet Sheet2
A1: name | C1: HAS TABLE
A2: tblProductTransactionprices | C2: =VLOOKUP($A2,Sheet1!A$2:$B$106,1,FALSE) -> #N/A
A3: tblMasterScheme | C3: =VLOOKUP($A3,Sheet1!A$2:$B$106,1,FALSE) -> #N/A
A4: tblTranOrderCollectionDetail | C4: =VLOOKUP($A4,Sheet1!A$2:$B$106,1,FALSE) -> #N/A
A5: tblTranOrderCollectionHeader | C5: =VLOOKUP($A5,Sheet1!A$2:$B$106,1,FALSE) -> #N/A
A6: tblAssignInvoicesDetail | C6: =VLOOKUP($A6,Sheet1!A$2:$B$106,1,FALSE) -> #N/A
A7: tblAssignInvoicesHeader | C7: =VLOOKUP($A7,Sheet1!A$2:$B$106,1,FALSE) -> #N/A
A8: tblTranOrderTakenHeader | C8: =VLOOKUP($A8,Sheet1!A$2:$B$106,1,FALSE) -> #N/A
A9: tblTranOrderTakenDetail | C9: =VLOOKUP($A9,Sheet1!A$2:$B$106,1,FALSE) -> #N/A
A10: tblAppPasswordSettings | C10: =VLOOKUP($A10,Sheet1!A$2:$B$106,1,FALSE) -> tblAppPasswordSettings
A11: tblMasterDiscountSchemeDetail | C11: =VLOOKUP($A11,Sheet1!A$2:$B$106,1,FALSE) -> #N/A
A12: tblMasterDiscountSchemeHeader | C12: =VLOOKUP($A12,Sheet1!A$2:$B$106,1,FALSE) -> #N/A
A13: tblFilterDates | C13: =VLOOKUP($A13,Sheet1!A$2:$B$106,1,FALSE) -> tblFilterDates
... A116: tblFAAccount | C116: =VLOOKUP($A116,Sheet1!A$2:$B$106,1,FALSE) -> tblFAAccount
